Workbook

Sheet Metadata
A1: role | B1: DMS Architect
A2: space | B2: cdf_idm
A3: externalId | B3: CogniteProcessIndustries
A4: version | B4: v1
A5: name | B5: Cognite process industries data model
A6: description | B6: Cognite process industries data model
A7: creator | B7: MISSING
A8: created | B8: 45533.576
A9: updated | B9: 45533.576
A10: sourceId | B10: http://purl.org/cognite/neat/data-model/verified/physical/cdf_idm/CogniteProcessIndustries/v1
A11: logical

Sheet Properties
A1: Definition of Properties
A2: View | B2: View Property | C2: Name | D2: Description | E2: Connection | F2: Value Type | G2: Min Count | H2: Max Count | I2: Immutable | J2: Default | K2: Container | L2: Container Property | M2: Index | N2: Constraint | O2: Logical | P2: Neat ID
A3: CogniteMaintenanceOrder | B3: mainAsset | C3: Main asset | D3: The primary asset (functional location) the maintenance order refers to. | E3: direct | F3: cdf_cdm:CogniteAsset(version=v1) | G3: 0 | H3: 1 | I3: FALSE | K3: CogniteMaintenanceOrder | L3: mainAsset | M3: mainAsset | P3: http://purl.org/cognite/neat/data-model/verified/physical/cdf_idm/CogniteProcessIndustries/v1/CogniteMaintenanceOrder/mainAsset
A4: CogniteMaintenanceOrder | B4: type | C4: Type | D4: The code for the type of maintenance order, for example, 'PM01' for 'Corrective maintenance'. | F4: text | G4: 0 | H4: 1 | I4: FALSE | K4: CogniteMaintenanceOrder | L4: type | M4: type | P4: http://purl.org/cognite/neat/data-model/verified/physical/cdf_idm/CogniteProcessIndustries/v1/CogniteMaintenanceOrder/type
A5: CogniteMaintenanceOrder | B5: status | C5: Status | D5: The lifecycle status of the maintenance order, for example, 'Partially complete'. It's often derived from the 'SystemStatus' field in SAP. | F5: text | G5: 0 | H5: 1 | I5: FALSE | K5: CogniteMaintenanceOrder | L5: status | M5: status | P5: http://purl.org/cognite/neat/data-model/verified/physical/cdf_idm/CogniteProcessIndustries/v1/CogniteMaintenanceOrder/status
A6: CogniteMaintenanceOrder | B6: priority | C6: Priority | D6: A number that shows how important this maintenance order is. Lower numbers mean it's more important, and 0 means it's the most important. | F6: int64 | G6: 0 | H6: 1 | I6: FALSE | K6: CogniteMaintenanceOrder | L6: priority | M6: priority | P6: http://purl.org/cognite/neat/data-model/verified/physical/cdf_idm/CogniteProcessIndustries/v1/CogniteMaintenanceOrder/priority
A7: CogniteMaintenanceOrder | B7: priorityDescription | C7: Priority description | D7: Describes the priority of the maintenance order. | F7: text | G7: 0 | H7: 1 | I7: FALSE | K7: CogniteMaintenanceOrder | L7: priorityDescription | P7: http://purl.org/cognite/neat/data-model/verified/physical/cdf_idm/CogniteProcessIndustries/v1/CogniteMaintenanceOrder/priorityDescription
A8: CogniteMaintenanceOrder | B8: operations | C8: Operations | D8: Lists the individual work items on the maintenance order. An automatically populated list of operations related to the maintenance order. | E8: reverse(property=maintenanceOrder) | F8: CogniteOperation | P8: http://purl.org/cognite/neat/data-model/verified/physical/cdf_idm/CogniteProcessIndustries/v1/CogniteMaintenanceOrder/operations
A9: cdf_cdm:CogniteSourceable(version=v1) | B9: sourceId | D9: Identifier from the source system | F9: text | G9: 0 | H9: 1 | I9: FALSE | K9: cdf_cdm:CogniteSourceable | L9: sourceId | M9: sourceId | P9: http://purl.org/cognite/neat/data-model/verified/physical/cdf_idm/CogniteProcessIndustries/v1/CogniteSourceable/sourceId
A10: cdf_cdm:CogniteSourceable(version=v1) | B10: sourceContext | D10: Context of the source id. For systems where the sourceId is globally unique, the sourceContext is expected to not be set. | F10: text | G10: 0 | H10: 1 | I10: FALSE | K10: cdf_cdm:CogniteSourceable | L10: sourceContext | P10: http://purl.org/cognite/neat/data-model/verified/physical/cdf_idm/CogniteProcessIndustries/v1/CogniteSourceable/sourceContext
A11: cdf_cdm:CogniteSourceable(version=v1) | B11: source | D11: Direct relation to a source system | E11: direct | F11: cdf_cdm:CogniteSourceSystem(version=v1) | G11: 0 | H11: 1 | I11: FALSE | K11: cdf_cdm:CogniteSourceable | L11: source | M11: source | P11: http://purl.org/cognite/neat/data-model/verified/physical/cdf_idm/CogniteProcessIndustries/v1/CogniteSourceable/source
A12: cdf_cdm:CogniteSourceable(version=v1) | B12: sourceCreatedTime | D12: When the instance was created in source system (if available) | F12: timestamp | G12: 0 | H12: 1 | I12: FALSE | K12: cdf_cdm:CogniteSourceable | L12: sourceCreatedTime | M12: sourceCreatedTime | P12: http://purl.org/cognite/neat/data-model/verified/physical/cdf_idm/CogniteProcessIndustries/v1/CogniteSourceable/sourceCreatedTime
A13: cdf_cdm:CogniteSourceable(version=v1) | B13: sourceUpdatedTime | D13: When the instance was last updated in the source system (if available) | F13: timestamp | G13: 0 | H13: 1 | I13: FALSE | K13: cdf_cdm:CogniteSourceable | L13: sourceUpdatedTime | M13: sourceUpdatedTime | P13: http://purl.org/cognite/neat/data-model/verified/physical/cdf_idm/CogniteProcessIndustries/v1/CogniteSourceable/sourceUpdatedTime
A14: cdf_cdm:CogniteSourceable(version=v1) | B14: sourceCreatedUser | D14: User identifier from the source system on who created the source data. This identifier is not guaranteed to match the user identifiers in CDF | F14: text | G14: 0 | H14: 1 | I14: FALSE | K14: cdf_cdm:CogniteSourceable | L14: sourceCreatedUser | P14: http://purl.org/cognite/neat/data-model/verified/physical/cdf_idm/CogniteProcessIndustries/v1/CogniteSourceable/sourceCreatedUser
A15: cdf_cdm:CogniteSourceable(version=v1) | B15: sourceUpdatedUser | D15: User identifier from the source system on who last updated the source data. This identifier is not guaranteed to match the user identifiers in CDF | F15: text | G15: 0 | H15: 1 | I15: FALSE | K15: cdf_cdm:CogniteSourceable | L15: sourceUpdatedUser | P15: http://purl.org/cognite/neat/data-model/verified/physical/cdf_idm/CogniteProcessIndustries/v1/CogniteSourceable/sourceUpdatedUser
A16: cdf_cdm:Cognite3DModel(version=v1) | B16: thumbnail | D16: Thumbnail of the 3D model | E16: direct | F16: cdf_cdm:CogniteFile(version=v1) | G16: 0 | H16: 1 | I16: FALSE | K16: cdf_cdm_3d:Cognite3DModel | L16: thumbnail | P16: http://purl.org/cognite/neat/data-model/verified/physical/cdf_idm/CogniteProcessIndustries/v1/Cognite3DModel/thumbnail
A17: cdf_cdm:Cognite3DModel(version=v1) | B17: type | D17: CAD, PointCloud or Image360 | F17: enum(collection=Cognite3DModel.type) | G17: 0 | H17: 1 | I17: FALSE | K17: cdf_cdm_3d:Cognite3DModel | L17: type | P17: http://purl.org/cognite/neat/data-model/verified/physical/cdf_idm/CogniteProcessIndustries/v1/Cognite3DModel/type
A18: cdf_cdm:CogniteUnit(version=v1) | B18: symbol | D18: The symbol for the unit of measurement | F18: text | G18: 0 | H18: 1 | I18: FALSE | K18: cdf_cdm:CogniteUnit | L18: symbol | P18: http://purl.org/cognite/neat/data-model/verified/physical/cdf_idm/CogniteProcessIndustries/v1/CogniteUnit/symbol
A19: cdf_cdm:CogniteUnit(version=v1) | B19: quantity | D19: Specifies the physical quantity the unit measures | F19: text | G19: 0 | H19: 1 | I19: FALSE | K19: cdf_cdm:CogniteUnit | L19: quantity | P19: http://purl.org/cognite/neat/data-model/verified/physical/cdf_idm/CogniteProcessIndustries/v1/CogniteUnit/quantity
A20: cdf_cdm:CogniteUnit(version=v1) | B20: source | D20: Source of the unit definition | F20: text | G20: 0 | H20: 1 | I20: FALSE | K20: cdf_cdm:CogniteUnit | L20: source | P20: http://purl.org/cognite/neat/data-model/verified/physical/cdf_idm/CogniteProcessIndustries/v1/CogniteUnit/source
A21: cdf_cdm:CogniteUnit(version=v1) | B21: sourceReference | D21: Reference to the source of the unit definition | F21: text | G21: 0 | H21: 1 | I21: FALSE | K21: cdf_cdm:CogniteUnit | L21: sourceReference | P21: http://purl.org/cognite/neat/data-model/verified/physical/cdf_idm/CogniteProcessIndustries/v1/CogniteUnit/sourceReference
A22: cdf_cdm:CogniteCADNode(version=v1) | B22: object3D | D22: Direct relation to object3D grouping for this node | E22: direct | F22: cdf_cdm:Cognite3DObject(version=v1) | G22: 0 | H22: 1 | I22: FALSE | K22: cdf_cdm_3d:CogniteCADNode | L22: object3D | P22: http://purl.org/cognite/neat/data-model/verified/physical/cdf_idm/CogniteProcessIndustries/v1/CogniteCADNode/object3D
A23: cdf_cdm:CogniteCADNode(version=v1) | B23: model3D | D23: Direct relation to Cognite3DModel | E23: direct | F23: cdf_cdm:CogniteCADModel(version=v1) | G23: 0 | H23: 1 | I23: FALSE | K23: cdf_cdm_3d:CogniteCADNode | L23: model3D | P23: http://purl.org/cognite/neat/data-model/verified/physical/cdf_idm/CogniteProcessIndustries/v1/CogniteCADNode/model3D
A24: cdf_cdm:CogniteCADNode(version=v1) | B24: cadNodeReference | D24: Reference to a node within a CAD model from the 3D API | F24: text | G24: 0 | H24: 1 | I24: FALSE | K24: cdf_cdm_3d:CogniteCADNode | L24: cadNodeReference | P24: http://purl.org/cognite/neat/data-model/verified/physical/cdf_idm/CogniteProcessIndustries/v1/CogniteCADNode/cadNodeReference
A25: cdf_cdm:CogniteCADNode(version=v1) | B25: revisions | D25: List of direct relations to instances of Cognite3DRevision which this CogniteCADNode exists in. | E25: direct | F25: cdf_cdm:CogniteCADRevision(version=v1) | G25: 0 | H25: 100 | I25: FALSE | K25: cdf_cdm_3d:CogniteCADNode | L25: revisions | P25: http://purl.org/cognite/neat/data-model/verified/physical/cdf_idm/CogniteProcessIndustries/v1/CogniteCADNode/revisions
A26: cdf_cdm:CogniteCADNode(version=v1) | B26: treeIndexes | D26: List of tree indexes in the same order as revisions. Used by Reveal and similar applications to map from CogniteCADNode to tree index | F26: int64 | G26: 0 | H26: 1000 | I26: FALSE | K26: cdf_cdm_3d:CogniteCADNode | L26: treeIndexes | P26: http://purl.org/cognite/neat/data-model/verified/physical/cdf_idm/CogniteProcessIndustries/v1/CogniteCADNode/treeIndexes
A27: cdf_cdm:CogniteCADNode(version=v1) | B27: subTreeSizes | D27: List of subtree sizes in the same order as revisions. Used by Reveal and similar applications to know how many nodes exists below this node in the hierarchy | F27: int64 | G27: 0 | H27: 1000 | I27: FALSE | K27: cdf_cdm_3d:CogniteCADNode | L27: subTreeSizes | P27: http://purl.org/cognite/neat/data-model/verified/physical/cdf_idm/CogniteProcessIndustries/v1/CogniteCADNode/subTreeSizes
A28: cdf_cdm:Cognite360ImageStation(version=v1) | B28: groupType | D28: Type of group | F28: enum(collection=Cognite3DGroup.groupType) | G28: 0 | H28: 1 | I28: FALSE | K28: cdf_cdm_3d:Cognite3DGroup | L28: groupType | P28: http://purl.org/cognite/neat/data-model/verified/physical/cdf_idm/CogniteProcessIndustries/v1/Cognite360ImageStation/groupType
A29: cdf_cdm:Cognite360Image(version=v1) | B29: collection360 | D29: Direct relation to Cognite360ImageCollection | E29: direct | F29: cdf_cdm:Cognite360ImageCollection(version=v1) | G29: 0 | H29: 1 | I29: FALSE | K29: cdf_cdm_3d:Cognite360Image | L29: collection360 | P29: http://purl.org/cognite/neat/data-model/verified/physical/cdf_idm/CogniteProcessIndustries/v1/Cognite360Image/collection360
A30: cdf_cdm:Cognite360Image(version=v1) | B30: station360 | D30: Direct relation to Cognite3DGroup instance that groups different Cognite360Image instances to the same station | E30: direct | F30: cdf_cdm:Cognite360ImageStation(version=v1) | G30: 0 | H30: 1 | I30: FALSE | K30: cdf_cdm_3d:Cognite360Image | L30: group3d | P30: http://purl.org/cognite/neat/data-model/verified/physical/cdf_idm/CogniteProcessIndustries/v1/Cognite360Image/station360
A31: cdf_cdm:Cognite360Image(version=v1) | B31: takenAt | D31: The timestamp when the 6 photos were taken | F31: timestamp | G31: 0 | H31: 1 | I31: FALSE | K31: cdf_cdm_3d:Cognite360Image | L31: takenAt | P31: http://purl.org/cognite/neat/data-model/verified/physical/cdf_idm/CogniteProcessIndustries/v1/Cognite360Image/takenAt
A32: cdf_cdm:CognitePointCloudModel(version=v1) | B32: revisions | D32: List of revisions for this PointCloud model | E32: reverse(property=model3D) | F32: cdf_cdm:CognitePointCloudRevision(version=v1) | P32: http://purl.org/cognite/neat/data-model/verified/physical/cdf_idm/CogniteProcessIndustries/v1/CognitePointCloudModel/revisions
A33: cdf_cdm:CogniteAnnotation(version=v1) | B33: confidence | D33: The confidence that the annotation is a good match | F33: float64 | G33: 0 | H33: 1 | I33: FALSE | K33: cdf_cdm:CogniteAnnotation | L33: confidence | P33: http://purl.org/cognite/neat/data-model/verified/physical/cdf_idm/CogniteProcessIndustries/v1/CogniteAnnotation/confidence
A34: cdf_cdm:CogniteAnnotation(version=v1) | B34: status | D34: The status of the annotation | F34: enum(collection=CogniteAnnotation.status) | G34: 0 | H34: 1 | I34: FALSE | K34: cdf_cdm:CogniteAnnotation | L34: status | P34: http://purl.org/cognite/neat/data-model/verified/physical/cdf_idm/CogniteProcessIndustries/v1/CogniteAnnotation/status
A35: cdf_cdm:CogniteFile(version=v1) | B35: assets | C35: Assets | D35: A list of assets this file is related to. | E35: direct | F35: cdf_cdm:CogniteAsset(version=v1) | G35: 0 | H35: 1200 | I35: FALSE | K35: cdf_cdm:CogniteFile | L35: assets | P35: http://purl.org/cognite/neat/data-model/verified/physical/cdf_idm/CogniteProcessIndustries/v1/CogniteFile/assets
A36: cdf_cdm:CogniteFile(version=v1) | B36: mimeType | C36: MIME type | D36: The MIME type of the file. | F36: text | G36: 0 | H36: 1 | I36: FALSE | K36: cdf_cdm:CogniteFile | L36: mimeType | P36: http://purl.org/cognite/neat/data-model/verified/physical/cdf_idm/CogniteProcessIndustries/v1/CogniteFile/mimeType
A37: cdf_cdm:CogniteFile(version=v1) | B37: directory | C37: Directory | D37: Contains the path elements from the source (if the source system has a file system hierarchy or similar.) | F37: text | G37: 0 | H37: 1 | I37: FALSE | K37: cdf_cdm:CogniteFile | L37: directory | P37: http://purl.org/cognite/neat/data-model/verified/physical/cdf_idm/CogniteProcessIndustries/v1/CogniteFile/directory
A38: cdf_cdm:CogniteFile(version=v1) | B38: isUploaded | C38: Is uploaded | D38: Specifies if the file content has been uploaded to Cognite Data Fusion or not. | F38: boolean | G38: 0 | H38: 1 | I38: FALSE | J38: FALSE | K38: cdf_cdm:CogniteFile | L38: isUploaded | P38: http://purl.org/cognite/neat/data-model/verified/physical/cdf_idm/CogniteProcessIndustries/v1/CogniteFile/isUploaded
A39: cdf_cdm:CogniteFile(version=v1) | B39: uploadedTime | C39: Uploaded time | D39: The time the file upload completed. | F39: timestamp | G39: 0 | H39: 1 | I39: FALSE | K39: cdf_cdm:CogniteFile | L39: uploadedTime | P39: http://purl.org/cognite/neat/data-model/verified/physical/cdf_idm/CogniteProcessIndustries/v1/CogniteFile/uploadedTime
A40: cdf_cdm:CogniteFile(version=v1) | B40: category | C40: Category | D40: Specifies the detected category the file belongs to. It's a direct relation to an instance of CogniteFileCategory. | E40: direct | F40: cdf_cdm:CogniteFileCategory(version=v1) | G40: 0 | H40: 1 | I40: FALSE | K40: cdf_cdm:CogniteFile | L40: category | P40: http://purl.org/cognite/neat/data-model/verified/physical/cdf_idm/CogniteProcessIndustries/v1/CogniteFile/category
...

Sheet Views
A1: Definition of Views
A2: View | B2: Name | C2: Description | D2: Implements | E2: Filter | F2: In Model | G2: Logical | H2: Neat ID
A3: CogniteMaintenanceOrder | B3: Maintenance order | C3: A formal request or directive to perform maintenance tasks such as repair, inspection, or servicing of equipment or assets. It's often called a 'work order'. | D3: cdf_cdm:CogniteDescribable(version=v1),cdf_cdm:CogniteSourceable(version=v1),cdf_cdm:CogniteSchedulable(version=v1),cdf_cdm:CogniteActivity(version=v1) | F3: TRUE | H3: http://purl.org/cognite/neat/data-model/verified/physical/cdf_idm/CogniteProcessIndustries/v1/CogniteMaintenanceOrder
A4: cdf_cdm:CogniteSourceable(version=v1) | F4: TRUE | H4: http://purl.org/cognite/neat/data-model/verified/physical/cdf_idm/CogniteProcessIndustries/v1/CogniteSourceable
A5: cdf_cdm:Cognite3DModel(version=v1) | C5: Groups revisions of 3D data of various kinds together (CAD, PointCloud, Image360) | D5: cdf_cdm:CogniteDescribable(version=v1) | F5: TRUE | H5: http://purl.org/cognite/neat/data-model/verified/physical/cdf_idm/CogniteProcessIndustries/v1/Cognite3DModel
A6: cdf_cdm:CogniteUnit(version=v1) | C6: Represents a single unit of measurement | D6: cdf_cdm:CogniteDescribable(version=v1) | F6: TRUE | H6: http://purl.org/cognite/neat/data-model/verified/physical/cdf_idm/CogniteProcessIndustries/v1/CogniteUnit
A7: cdf_cdm:CogniteCADNode(version=v1) | C7: Represents nodes from the 3D model that have been contextualized | D7: cdf_cdm:CogniteDescribable(version=v1) | F7: TRUE | H7: http://purl.org/cognite/neat/data-model/verified/physical/cdf_idm/CogniteProcessIndustries/v1/CogniteCADNode
A8: cdf_cdm:Cognite360ImageStation(version=v1) | C8: A way to group images across collections. Used for creating visual scan history | D8: cdf_cdm:CogniteDescribable(version=v1) | E8: rawFilter({"and": [{"hasData": [{"type": "container", "space": "cdf_cdm_3d", "externalId": "Cognite3DGroup"}]}, {"equals": {"property": ["cdf_cdm_3d", "Cognite3DGroup", "groupType"], "value": "Station360"}}]}) | F8: TRUE | H8: http://purl.org/cognite/neat/data-model/verified/physical/cdf_idm/CogniteProcessIndustries/v1/Cognite360ImageStation
A9: cdf_cdm:Cognite360Image(version=v1) | D9: cdf_cdm:Cognite3DTransformation(version=v1),cdf_cdm:CogniteCubeMap(version=v1) | F9: TRUE | H9: http://purl.org/cognite/neat/data-model/verified/physical/cdf_idm/CogniteProcessIndustries/v1/Cognite360Image
A10: cdf_cdm:CognitePointCloudModel(version=v1) | C10: Navigational aid for traversing CognitePointCloudModel instances | D10: cdf_cdm:CogniteDescribable(version=v1),cdf_cdm:Cognite3DModel(version=v1) | E10: rawFilter({"and": [{"hasData": [{"type": "container", "space": "cdf_cdm_3d", "externalId": "Cognite3DModel"}]}, {"equals": {"property": ["cdf_cdm_3d", "Cognite3DModel", "type"], "value": "PointCloud"}}]}) | F10: TRUE | H10: http://purl.org/cognite/neat/data-model/verified/physical/cdf_idm/CogniteProcessIndustries/v1/CognitePointCloudModel
A11: cdf_cdm:CogniteAnnotation(version=v1) | C11: Annotation represents contextualization results or links | D11: cdf_cdm:CogniteDescribable(version=v1),cdf_cdm:CogniteSourceable(version=v1) | F11: TRUE | H11: http://purl.org/cognite/neat/data-model/verified/physical/cdf_idm/CogniteProcessIndustries/v1/CogniteAnnotation
A12: cdf_cdm:CogniteFile(version=v1) | B12: File | C12: Represents files. | D12: cdf_cdm:CogniteDescribable(version=v1),cdf_cdm:CogniteSourceable(version=v1) | F12: TRUE | H12: http://purl.org/cognite/neat/data-model/verified/physical/cdf_idm/CogniteProcessIndustries/v1/CogniteFile
A13: cdf_cdm:CognitePointCloudRevision(version=v1) | C13: Navigational aid for traversing CognitePointCloudRevision instances | D13: cdf_cdm:Cognite3DRevision(version=v1) | E13: rawFilter({"and": [{"hasData": [{"type": "container", "space": "cdf_cdm_3d", "externalId": "Cognite3DRevision"}]}, {"equals": {"property": ["cdf_cdm_3d", "Cognite3DModel", "type"], "value": "PointCloud"}}]}) | F13: TRUE | H13: http://purl.org/cognite/neat/data-model/verified/physical/cdf_idm/CogniteProcessIndustries/v1/CognitePointCloudRevision
A14: cdf_cdm:CogniteActivity(version=v1) | B14: Activity | C14: Represents activities. Activities typically happen over a period and have a start and end time. | D14: cdf_cdm:CogniteDescribable(version=v1),cdf_cdm:CogniteSourceable(version=v1),cdf_cdm:CogniteSchedulable(version=v1) | F14: TRUE | H14: http://purl.org/cognite/neat/data-model/verified/physical/cdf_idm/CogniteProcessIndustries/v1/CogniteActivity
A15: cdf_cdm:CogniteCADModel(version=v1) | C15: Navigational aid for traversing CogniteCADModel instances | D15: cdf_cdm:CogniteDescribable(version=v1),cdf_cdm:Cognite3DModel(version=v1) | E15: rawFilter({"and": [{"hasData": [{"type": "container", "space": "cdf_cdm_3d", "externalId": "Cognite3DModel"}]}, {"equals": {"property": ["cdf_cdm_3d", "Cognite3DModel", "type"], "value": "CAD"}}]}) | F15: TRUE | H15: http://purl.org/cognite/neat/data-model/verified/physical/cdf_idm/CogniteProcessIndustries/v1/CogniteCADModel
A16: cdf_cdm:CogniteAsset(version=v1) | B16: Asset | C16: Assets represent systems that support industrial functions or processes. Assets are often called 'functional location'. | D16: cdf_cdm:CogniteVisualizable(version=v1),cdf_cdm:CogniteDescribable(version=v1),cdf_cdm:CogniteSourceable(version=v1) | F16: TRUE | H16: http://purl.org/cognite/neat/data-model/verified/physical/cdf_idm/CogniteProcessIndustries/v1/CogniteAsset
A17: cdf_cdm:CogniteEquipmentType(version=v1) | B17: Equipment type | C17: Represents the type of equipment. | D17: cdf_cdm:CogniteDescribable(version=v1) | F17: TRUE | H17: http://purl.org/cognite/neat/data-model/verified/physical/cdf_idm/CogniteProcessIndustries/v1/CogniteEquipmentType
A18: cdf_cdm:Cognite3DRevision(version=v1) | C18: Shared revision information for various 3D data types. Normally not used directly, but through CognitePointCloudRevision, Image360Collection or CogniteCADRevision | F18: TRUE | H18: http://purl.org/cognite/neat/data-model/verified/physical/cdf_idm/CogniteProcessIndustries/v1/Cognite3DRevision
A19: cdf_cdm:Cognite360ImageAnnotation(version=v1) | D19: cdf_cdm:CogniteDescribable(version=v1),cdf_cdm:CogniteSourceable(version=v1),cdf_cdm:CogniteAnnotation(version=v1) | F19: TRUE | H19: http://purl.org/cognite/neat/data-model/verified/physical/cdf_idm/CogniteProcessIndustries/v1/Cognite360ImageAnnotation
A20: cdf_cdm:CogniteDiagramAnnotation(version=v1) | C20: Annotation for diagrams | D20: cdf_cdm:CogniteDescribable(version=v1),cdf_cdm:CogniteSourceable(version=v1),cdf_cdm:CogniteAnnotation(version=v1) | F20: TRUE | H20: http://purl.org/cognite/neat/data-model/verified/physical/cdf_idm/CogniteProcessIndustries/v1/CogniteDiagramAnnotation
A21: cdf_cdm:CogniteVisualizable(version=v1) | C21: CogniteVisualizable defines the standard way to reference a related 3D resource | F21: TRUE | H21: http://purl.org/cognite/neat/data-model/verified/physical/cdf_idm/CogniteProcessIndustries/v1/CogniteVisualizable
A22: cdf_cdm:Cognite360ImageCollection(version=v1) | C22: Represents a logical collection of Cognite360Image instances | D22: cdf_cdm:CogniteDescribable(version=v1),cdf_cdm:Cognite3DRevision(version=v1) | E22: rawFilter({"and": [{"hasData": [{"type": "container", "space": "cdf_cdm_3d", "externalId": "Cognite3DRevision"}]}, {"equals": {"property": ["cdf_cdm_3d", "Cognite3DModel", "type"], "value": "Image360"}}]}) | F22: TRUE | H22: http://purl.org/cognite/neat/data-model/verified/physical/cdf_idm/CogniteProcessIndustries/v1/Cognite360ImageCollection
A23: CogniteNotification | B23: Notification | C23: A formal record to report maintenance issues, defects, or requests, starting the process for planning and running maintenance activities. | D23: cdf_cdm:CogniteDescribable(version=v1),cdf_cdm:CogniteSourceable(version=v1),cdf_cdm:CogniteSchedulable(version=v1) | F23: TRUE | H23: http://purl.org/cognite/neat/data-model/verified/physical/cdf_idm/CogniteProcessIndustries/v1/CogniteNotification
A24: cdf_cdm:Cognite3DTransformation(version=v1) | C24: The Cognite3DTransformation object defines a comprehensive 3D transformation, enabling precise adjustments to an object's position, orientation, and size in the 3D coordinate system. It allows for the translation of objects along the three spatial axes, rotation around these axes using Euler angles, and scaling along each axis to modify the object's dimensions. The object's transformation is defined in "CDF space", a coordinate system where the positive Z axis is the up direction | F24: TRUE | H24: http://purl.org/cognite/neat/data-model/verified/physical/cdf_idm/CogniteProcessIndustries/v1/Cognite3DTransformation
A25: cdf_cdm:CogniteTimeSeries(version=v1) | B25: Time series | C25: Represents a series of data points in time order. | D25: cdf_cdm:CogniteDescribable(version=v1),cdf_cdm:CogniteSourceable(version=v1) | F25: TRUE | H25: http://purl.org/cognite/neat/data-model/verified/physical/cdf_idm/CogniteProcessIndustries/v1/CogniteTimeSeries
A26: CogniteOperation | B26: Operation | C26: Operations represent a specific part of the work included in a maintenance order. Often called a 'work order item'. | D26: cdf_cdm:CogniteDescribable(version=v1),cdf_cdm:CogniteSourceable(version=v1),cdf_cdm:CogniteSchedulable(version=v1),cdf_cdm:CogniteActivity(version=v1) | F26: TRUE | H26: http://purl.org/cognite/neat/data-model/verified/physical/cdf_idm/CogniteProcessIndustries/v1/CogniteOperation
A27: cdf_cdm:CognitePointCloudVolume(version=v1) | C27: PointCloud volume definition | D27: cdf_cdm:CogniteDescribable(version=v1) | F27: TRUE | H27: http://purl.org/cognite/neat/data-model/verified/physical/cdf_idm/CogniteProcessIndustries/v1/CognitePointCloudVolume
A28: cdf_cdm:CogniteFileCategory(version=v1) | B28: File category | C28: Represents the categories of files as determined by contextualization or categorization. | D28: cdf_cdm:CogniteDescribable(version=v1) | F28: TRUE | H28: http://purl.org/cognite/neat/data-model/verified/physical/cdf_idm/CogniteProcessIndustries/v1/CogniteFileCategory
A29: cdf_cdm:Cognite360ImageModel(version=v1) | C29: Navigational aid for traversing Cognite360ImageModel instances | D29: cdf_cdm:CogniteDescribable(version=v1),cdf_cdm:Cognite3DModel(version=v1) | E29: rawFilter({"and": [{"hasData": [{"type": "container", "space": "cdf_cdm_3d", "externalId": "Cognite3DModel"}]}, {"equals": {"property": ["cdf_cdm_3d", "Cognite3DModel", "type"], "value": "Image360"}}]}) | F29: TRUE | H29: http://purl.org/cognite/neat/data-model/verified/physical/cdf_idm/CogniteProcessIndustries/v1/Cognite360ImageModel
A30: cdf_cdm:CogniteAssetType(version=v1) | B30: Asset type | C30: Represents the type of an asset. | D30: cdf_cdm:CogniteDescribable(version=v1) | F30: TRUE | H30: http://purl.org/cognite/neat/data-model/verified/physical/cdf_idm/CogniteProcessIndustries/v1/CogniteAssetType
A31: cdf_cdm:CogniteCubeMap(version=v1) | C31: The cube map holds references to 6 images in used to visually represent the surrounding environment | F31: TRUE | H31: http://purl.org/cognite/neat/data-model/verified/physical/cdf_idm/CogniteProcessIndustries/v1/CogniteCubeMap
A32: cdf_cdm:CogniteSourceSystem(version=v1) | C32: The CogniteSourceSystem core concept is used to standardize the way source system is stored. | D32: cdf_cdm:CogniteDescribable(version=v1) | F32: TRUE | H32: http://purl.org/cognite/neat/data-model/verified/physical/cdf_idm/CogniteProcessIndustries/v1/CogniteSourceSystem
A33: cdf_cdm:CogniteCADRevision(version=v1) | D33: cdf_cdm:Cognite3DRevision(version=v1) | E33: rawFilter({"and": [{"hasData": [{"type": "container", "space": "cdf_cdm_3d", "externalId": "Cognite3DRevision"}]}, {"equals": {"property": ["cdf_cdm_3d", "Cognite3DModel", "type"], "value": "CAD"}}]}) | F33: TRUE | H33: http://purl.org/cognite/neat/data-model/verified/physical/cdf_idm/CogniteProcessIndustries/v1/CogniteCADRevision
A34: cdf_cdm:CogniteSchedulable(version=v1) | C34: CogniteSchedulable represents the metadata about when an activity (or similar) starts and ends. | F34: TRUE | H34: http://purl.org/cognite/neat/data-model/verified/physical/cdf_idm/CogniteProcessIndustries/v1/CogniteSchedulable
A35: cdf_cdm:CogniteDescribable(version=v1) | C35: The describable core concept is used as a standard way of holding the bare minimum of information about the instance | F35: TRUE | H35: http://purl.org/cognite/neat/data-model/verified/physical/cdf_idm/CogniteProcessIndustries/v1/CogniteDescribable
A36: cdf_cdm:CogniteAssetClass(version=v1) | B36: Asset class | C36: Represents the class of an asset. | D36: cdf_cdm:CogniteDescribable(version=v1) | F36: TRUE | H36: http://purl.org/cognite/neat/data-model/verified/physical/cdf_idm/CogniteProcessIndustries/v1/CogniteAssetClass
A37: cdf_cdm:CogniteEquipment(version=v1) | B37: Equipment | C37: Equipment represents physical supplies or devices. | D37: cdf_cdm:CogniteDescribable(version=v1),cdf_cdm:CogniteSourceable(version=v1) | F37: TRUE | H37: http://purl.org/cognite/neat/data-model/verified/physical/cdf_idm/CogniteProcessIndustries/v1/CogniteEquipment
A38: cdf_cdm:Cognite3DObject(version=v1) | C38: This is the virtual position representation of an object in the physical world, connecting an asset to one or more 3D resources | D38: cdf_cdm:CogniteDescribable(version=v1) | F38: TRUE | H38: http://purl.org/cognite/neat/data-model/verified/physical/cdf_idm/CogniteProcessIndustries/v1/Cognite3DObject

Sheet Containers
A1: Definition of Containers
A2: Container | B2: Name | C2: Description | D2: Constraint | E2: Used For | F2: Neat ID
A3: cdf_cdm:CogniteTimeSeries | D3: cdf_cdm:CogniteDescribable,cdf_cdm:CogniteSourceable | E3: node
A4: cdf_cdm:CogniteSourceSystem | C4: The CogniteSourceSystem core concept is used to standardize the way source system is stored. | E4: node
A5: CogniteMaintenanceOrder | E5: node
A6: cdf_cdm:CogniteAsset | C6: The asset is the bare bone representation of assets in our asset centric world | D6: cdf_cdm:CogniteDescribable,cdf_cdm:CogniteVisualizable,cdf_cdm:CogniteSourceable | E6: node
A7: CogniteOperation | E7: node
A8: cdf_cdm:CogniteFile | C8: This concept models the underlying file from the Files resource type | D8: cdf_cdm:CogniteDescribable,cdf_cdm:CogniteSourceable | E8: node
A9: cdf_cdm_3d:CogniteCADNode | E9: node
A10: cdf_cdm:CogniteUnit | C10: Represents a single unit of measurement | D10: cdf_cdm:CogniteDescribable | E10: node
A11: cdf_cdm:CogniteActivity | C11: Represent an activity | D11: cdf_cdm:CogniteDescribable,cdf_cdm:CogniteSourceable,cdf_cdm:CogniteSchedulable | E11: node
A12: cdf_cdm:CogniteEquipmentType | C12: This identifies the type of an equipment | D12: cdf_cdm:CogniteDescribable | E12: node
A13: cdf_cdm:CogniteSourceable | C13: The CogniteSourceable core concept is used to standardize the way source information is stored. | E13: all
A14: cdf_cdm_3d:CogniteCubeMap | E14: node
A15: cdf_cdm_3d:Cognite360Image | E15: node
A16: cdf_cdm_3d:Cognite360ImageAnnotation | E16: edge
A17: cdf_cdm_3d:CogniteCADRevision | E17: node
A18: cdf_cdm_3d:Cognite3DGroup | E18: node
A19: cdf_cdm_3d:Cognite3DRevision | E19: node
A20: cdf_cdm:CogniteVisualizable | C20: CogniteVisualizable defines the standard way to reference a related 3D resource | E20: node
A21: cdf_cdm_3d:CognitePointCloudRevision | E21: node
A22: cdf_cdm:CogniteDescribable | C22: The describable core concept is used as a standard way of holding the bare minimum of information about the instance. | E22: all
A23: cdf_cdm:CogniteAnnotation | C23: Annotation represents contextualization results or links | D23: cdf_cdm:CogniteDescribable,cdf_cdm:CogniteSourceable | E23: edge
A24: cdf_cdm:CogniteFileCategory | C24: Specifies the category for a file (as a result of categorization/classification)) | D24: cdf_cdm:CogniteDescribable | E24: node
A25: cdf_cdm_3d:CognitePointCloudVolume | E25: node
A26: cdf_cdm_3d:Cognite3DModel | E26: node
A27: cdf_cdm_3d:Cognite3DTransformation | E27: all
A28: CogniteNotification | E28: node
A29: cdf_cdm:CogniteEquipment | C29: Represent a physical piece of equipment | D29: cdf_cdm:CogniteDescribable,cdf_cdm:CogniteSourceable | E29: node
A30: cdf_cdm_3d:Cognite3DObject | E30: node
A31: cdf_cdm:CogniteAssetType | C31: This identifies the type of an asset | D31: cdf_cdm:CogniteDescribable | E31: node
A32: cdf_cdm:CogniteAssetClass | C32: This identifies the class of an asset | D32: cdf_cdm:CogniteDescribable | E32: node
A33: cdf_cdm:CogniteSchedulable | C33: CogniteSchedulable represents the metadata about when an activity (or similar) starts and ends | E33: node
A34: cdf_cdm:CogniteDiagramAnnotation | D34: cdf_cdm:CogniteDescribable,cdf_cdm:CogniteSourceable,cdf_cdm:CogniteAnnotation | E34: edge

Sheet Enum
A1: Definition of Enum Collections
A2: Collection | B2: Value | C2: Name | D2: Description | E2: Neat ID
A3: CogniteTimeSeries.type | B3: string | C3: string | D3: Time series with string data points.
A4: CogniteTimeSeries.type | B4: numeric | C4: numeric | D4: Time series with double floating point data points.
A5: Cognite3DGroup.groupType | B5: Station360 | C5: Station360
A6: Cognite3DRevision.type | B6: CAD | C6: CAD
A7: Cognite3DRevision.type | B7: PointCloud | C7: PointCloud
A8: Cognite3DRevision.type | B8: Image360 | C8: Image360
A9: Cognite3DRevision.status | B9: Queued | C9: Queued
A10: Cognite3DRevision.status | B10: Processing | C10: Processing
A11: Cognite3DRevision.status | B11: Done | C11: Done
A12: Cognite3DRevision.status | B12: Failed | C12: Failed
A13: CogniteAnnotation.status | B13: Suggested | C13: Suggested
A14: CogniteAnnotation.status | B14: Approved | C14: Approved
A15: CogniteAnnotation.status | B15: Rejected | C15: Rejected
A16: CognitePointCloudVolume.volumeType | B16: Cylinder | C16: Cylinder
... A20: Cognite3DModel.type | B20: Image360 | C20: Image360

Sheet Nodes
A1: Definition of Nodes
A2: Node | B2: Usage | C2: Name | D2: Description | E2: Neat ID

Sheet _helper
A1: =IF(ISBLANK(Views!A3), "", Views!A3) | B1: =IF(ISBLANK(Views!A3), "", Views!A3) | C1: boolean | D1: =IF(ISBLANK(Containers!A3), "", Containers!A3) | E1: TRUE | F1: node
A2: =IF(ISBLANK(Views!A4), "", Views!A4) | B2: =IF(ISBLANK(Views!A4), "", Views!A4) | C2: float32 | D2: =IF(ISBLANK(Containers!A4), "", Containers!A4) | E2: FALSE | F2: edge
A3: =IF(ISBLANK(Views!A5), "", Views!A5) | B3: =IF(ISBLANK(Views!A5), "", Views!A5) | C3: float64 | D3: =IF(ISBLANK(Containers!A5), "", Containers!A5) | F3: all
A4: =IF(ISBLANK(Views!A6), "", Views!A6) | B4: =IF(ISBLANK(Views!A6), "", Views!A6) | C4: int32 | D4: =IF(ISBLANK(Containers!A6), "", Containers!A6)
A5: =IF(ISBLANK(Views!A7), "", Views!A7) | B5: =IF(ISBLANK(Views!A7), "", Views!A7) | C5: int64 | D5: =IF(ISBLANK(Containers!A7), "", Containers!A7)
A6: =IF(ISBLANK(Views!A8), "", Views!A8) | B6: =IF(ISBLANK(Views!A8), "", Views!A8) | C6: text | D6: =IF(ISBLANK(Containers!A8), "", Containers!A8)
A7: =IF(ISBLANK(Views!A9), "", Views!A9) | B7: =IF(ISBLANK(Views!A9), "", Views!A9) | C7: timestamp | D7: =IF(ISBLANK(Containers!A9), "", Containers!A9)
A8: =IF(ISBLANK(Views!A10), "", Views!A10) | B8: =IF(ISBLANK(Views!A10), "", Views!A10) | C8: date | D8: =IF(ISBLANK(Containers!A10), "", Containers!A10)
A9: =IF(ISBLANK(Views!A11), "", Views!A11) | B9: =IF(ISBLANK(Views!A11), "", Views!A11) | D9: =IF(ISBLANK(Containers!A11), "", Containers!A11)
A10: =IF(ISBLANK(Views!A12), "", Views!A12) | B10: =IF(ISBLANK(Views!A12), "", Views!A12) | D10: =IF(ISBLANK(Containers!A12), "", Containers!A12)
A11: =IF(ISBLANK(Views!A13), "", Views!A13) | B11: =IF(ISBLANK(Views!A13), "", Views!A13) | D11: =IF(ISBLANK(Containers!A13), "", Containers!A13)
A12: =IF(ISBLANK(Views!A14), "", Views!A14) | B12: =IF(ISBLANK(Views!A14), "", Views!A14) | D12: =IF(ISBLANK(Containers!A14), "", Containers!A14)
A13: =IF(ISBLANK(Views!A15), "", Views!A15) | B13: =IF(ISBLANK(Views!A15), "", Views!A15) | D13: =IF(ISBLANK(Containers!A15), "", Containers!A15)
A14: =IF(ISBLANK(Views!A16), "", Views!A16) | B14: =IF(ISBLANK(Views!A16), "", Views!A16) | C14: =IF(ISBLANK(Views!A3), "", Views!A3) | D14: =IF(ISBLANK(Containers!A16), "", Containers!A16)
A15: =IF(ISBLANK(Views!A17), "", Views!A17) | B15: =IF(ISBLANK(Views!A17), "", Views!A17) | C15: =IF(ISBLANK(Views!A4), "", Views!A4) | D15: =IF(ISBLANK(Containers!A17), "", Containers!A17)
A16: =IF(ISBLANK(Views!A18), "", Views!A18) | B16: =IF(ISBLANK(Views!A18), "", Views!A18) | C16: =IF(ISBLANK(Views!A5), "", Views!A5) | D16: =IF(ISBLANK(Containers!A18), "", Containers!A18)
A17: =IF(ISBLANK(Views!A19), "", Views!A19) | B17: =IF(ISBLANK(Views!A19), "", Views!A19) | C17: =IF(ISBLANK(Views!A6), "", Views!A6) | D17: =IF(ISBLANK(Containers!A19), "", Containers!A19)
A18: =IF(ISBLANK(Views!A20), "", Views!A20) | B18: =IF(ISBLANK(Views!A20), "", Views!A20) | C18: =IF(ISBLANK(Views!A7), "", Views!A7) | D18: =IF(ISBLANK(Containers!A20), "", Containers!A20)
A19: =IF(ISBLANK(Views!A21), "", Views!A21) | B19: =IF(ISBLANK(Views!A21), "", Views!A21) | C19: =IF(ISBLANK(Views!A8), "", Views!A8) | D19: =IF(ISBLANK(Containers!A21), "", Containers!A21)
A20: =IF(ISBLANK(Views!A22), "", Views!A22) | B20: =IF(ISBLANK(Views!A22), "", Views!A22) | C20: =IF(ISBLANK(Views!A9), "", Views!A9) | D20: =IF(ISBLANK(Containers!A22), "", Containers!A22)
A21: =IF(ISBLANK(Views!A23), "", Views!A23) | B21: =IF(ISBLANK(Views!A23), "", Views!A23) | C21: =IF(ISBLANK(Views!A10), "", Views!A10) | D21: =IF(ISBLANK(Containers!A23), "", Containers!A23)
A22: =IF(ISBLANK(Views!A24), "", Views!A24) | B22: =IF(ISBLANK(Views!A24), "", Views!A24) | C22: =IF(ISBLANK(Views!A11), "", Views!A11) | D22: =IF(ISBLANK(Containers!A24), "", Containers!A24)
A23: =IF(ISBLANK(Views!A25), "", Views!A25) | B23: =IF(ISBLANK(Views!A25), "", Views!A25) | C23: =IF(ISBLANK(Views!A12), "", Views!A12) | D23: =IF(ISBLANK(Containers!A25), "", Containers!A25)
A24: =IF(ISBLANK(Views!A26), "", Views!A26) | B24: =IF(ISBLANK(Views!A26), "", Views!A26) | C24: =IF(ISBLANK(Views!A13), "", Views!A13) | D24: =IF(ISBLANK(Containers!A26), "", Containers!A26)
A25: =IF(ISBLANK(Views!A27), "", Views!A27) | B25: =IF(ISBLANK(Views!A27), "", Views!A27) | C25: =IF(ISBLANK(Views!A14), "", Views!A14) | D25: =IF(ISBLANK(Containers!A27), "", Containers!A27)
... A100: =IF(ISBLANK(Views!A102), "", Views!A102) | B100: =IF(ISBLANK(Views!A102), "", Views!A102) | C100: =IF(ISBLANK(Views!A89), "", Views!A89) | D100: =IF(ISBLANK(Containers!A102), "", Containers!A102)
C101: =IF(ISBLANK(Views!A90), "", Views!A90)
C102: =IF(ISBLANK(Views!A91), "", Views!A91)
C103: =IF(ISBLANK(Views!A92), "", Views!A92)
C104: =IF(ISBLANK(Views!A93), "", Views!A93)
C105: =IF(ISBLANK(Views!A94), "", Views!A94)
C106: =IF(ISBLANK(Views!A95), "", Views!A95)
C107: =IF(ISBLANK(Views!A96), "", Views!A96)
C108: =IF(ISBLANK(Views!A97), "", Views!A97)
C109: =IF(ISBLANK(Views!A98), "", Views!A98)
C110: =IF(ISBLANK(Views!A99), "", Views!A99)
C111: =IF(ISBLANK(Views!A100), "", Views!A100)
C112: =IF(ISBLANK(Views!A101), "", Views!A101)
C113: =IF(ISBLANK(Views!A102), "", Views!A102)
